Workbook

Sheet DRIVER OPERATIVI
A1: DRIVER OPERATIVI | B1: Anno 1 | C1: Anno 2 | D1: Anno 3 | E1: Anno 4 | F1: Anno 5
A2: QUANTITATIVI DI ENERGIA (MWh) | B2: 0 | C2: 0 | D2: 0 | E2: 0 | F2: 0
A3: Produzione Fotovoltaica Totale (MWh) | B3: =B4+B5+B6 | C3: =C4+C5+C6 | D3: =D4+D5+D6 | E3: =E4+E5+E6 | F3: =F4+F5+F6
A4: di cui: Energia FV in Autoconsumo / PPA (MWh) | B4: 5559.5357 | C4: 5540.0773 | D4: 5520.6189 | E4: 5501.1605 | F4: 5481.7022
A5: di cui: Energia FV immessa in Rete / RID (MWh) | B5: 7940.704 | C5: 7912.9116 | D5: 7885.1191 | E5: 7857.3266 | F5: 7829.5342
A6: di cui: Energia FV per Carica BESS (MWh) | B6: 0 | C6: 0 | D6: 0 | E6: 0 | F6: 0
A7: Scarica BESS Totale (MWh) | B7: =B8+B9 | C7: =C8+C9 | D7: =D8+D9 | E7: =E8+E9 | F7: =F8+F9
A8: di cui: Scarica BESS per Autoconsumo / PPA (MWh) | B8: 0 | C8: 0 | D8: 0 | E8: 0 | F8: 0
A9: di cui: Scarica BESS immessa in Rete / RID (MWh) | B9: =B10+B11 | C9: =C10+C11 | D9: =D10+D11 | E9: =E10+E11 | F9: =F10+F11
A10: - di cui: Scarica Rete da Arbitraggio (MWh) | B10: 0 | C10: 0 | D10: 0 | E10: 0 | F10: 0
A11: - di cui: Scarica Rete da Timeshifting (MWh) | B11: 0 | C11: 0 | D11: 0 | E11: 0 | F11: 0
A12: Carica BESS da Rete (MWh) | B12: 0 | C12: 0 | D12: 0 | E12: 0 | F12: 0
A13: Perdite di Efficienza BESS (RTE) (MWh) | B13: 0 | C13: 0 | D13: 0 | E13: 0 | F13: 0
A15: FATTORI MACROECONOMICI | B15: 0 | C15: 0 | D15: 0 | E15: 0 | F15: 0
A16: Tasso di Inflazione (%) | B16: 0.02 | C16: 0.02 | D16: 0.02 | E16: 0.02 | F16: 0.02
A17: Premio Commerciale PPA (%) | B17: 0.05 | C17: 0.05 | D17: 0.05 | E17: 0.05 | F17: 0.05
A18: Potenza Totale Impianti (kWp) | B18: 8186.2 | C18: 8186.2 | D18: 8186.2 | E18: 8186.2 | F18: 8186.2
A20: VALORI UNITARI DI RICAVO & COSTO (€/MWh) | B20: 0 | C20: 0 | D20: 0 | E20: 0 | F20: 0
A21: Valore Unitario Medio Ponderato FV (€/MWh) | B21: =IFERROR((B22*B4 + B23*B5)/(B4+B5), 0) | C21: =IFERROR((C22*C4 + C23*C5)/(C4+C5), 0) | D21: =IFERROR((D22*D4 + D23*D5)/(D4+D5), 0) | E21: =IFERROR((E22*E4 + E23*E5)/(E4+E5), 0) | F21: =IFERROR((F22*F4 + F23*F5)/(F4+F5), 0)
A22: Prezzo Unitario PPA On-Site FV (€/MWh) | B22: 140 | C22: 140 | D22: 140 | E22: 140 | F22: 140
A23: Prezzo Unitario RID FV (€/MWh) | B23: 107.17541 | C23: 101.81664 | D23: 96.725809 | E23: 91.889519 | F23: 87.295043
A24: Valore Unitario Medio Ponderato BESS (€/MWh) | B24: =IFERROR((B25*B8 + B26*B9)/B7, 0) | C24: =IFERROR((C25*C8 + C26*C9)/C7, 0) | D24: =IFERROR((D25*D8 + D26*D9)/D7, 0) | E24: =IFERROR((E25*E8 + E26*E9)/E7, 0) | F24: =IFERROR((F25*F8 + F26*F9)/F7, 0)
A25: Prezzo Unitario PPA On-Site BESS (€/MWh) | B25: 0 | C25: 0 | D25: 0 | E25: 0 | F25: 0
A26: Prezzo Unitario RID BESS (€/MWh) | B26: =IFERROR((B27*B10 + B28*B11)/B9, 0) | C26: =IFERROR((C27*C10 + C28*C11)/C9, 0) | D26: =IFERROR((D27*D10 + D28*D11)/D9, 0) | E26: =IFERROR((E27*E10 + E28*E11)/E9, 0) | F26: =IFERROR((F27*F10 + F28*F11)/F9, 0)
A27: - di cui: Prezzo di Vendita Arbitraggio (€/MWh) | B27: 0 | C27: 0 | D27: 0 | E27: 0 | F27: 0
A28: - di cui: Prezzo di Vendita Timeshifting (€/MWh) | B28: 0 | C28: 0 | D28: 0 | E28: 0 | F28: 0
A29: Costo Unitario Ricarica BESS da Rete (€/MWh) | B29: 0 | C29: 0 | D29: 0 | E29: 0 | F29: 0

Sheet CAPEX
A1: Voci di Costo CAPEX | B1: Guasticce (kW) | C1: Castenaso (kW) | D1: TOTALE PORTAFOGLIO | E1: Aliquota Ammortamento (%)
A2: EPC Solar (€) | B2: 2614500 | C2: 2501875 | D2: =SUM(B2:C2) | E2: 0.09
A3: BESS (€) | B3: 0 | C3: 0 | D3: =SUM(B3:C3) | E3: 0.09
A4: Connessione (€) | B4: 62240 | C4: 43261 | D4: =SUM(B4:C4) | E4: 0.09
A5: Sviluppo (€) | B5: 0 | C5: 0 | D5: =SUM(B5:C5) | E5: 0.09
A6: SPV Acquisizione (€) | B6: 400000 | C6: 400000 | D6: =SUM(B6:C6)
A7: Terreni (Acquisto) (€) | B7: 0 | C7: 379728 | D7: =SUM(B7:C7)
A8: Terreni (DDS Attualizzato) (€) | B8: 396000 | C8: 0 | D8: =SUM(B8:C8) | E8: 0.09
A10: TOTALE CAPEX (€) | B10: =SUM(B2:B8) | C10: =SUM(C2:C8) | D10: =SUM(D2:D8)
A12: AMMORTAMENTO CIVILISTICO
A13: Quota Ammortamento EPC Solar | B13: =ROUND(B2 * E2, 0) | C13: =ROUND(C2 * E2, 0) | D13: =ROUND(D2 * E2, 0)
A14: Quota Ammortamento BESS | B14: =ROUND(B3 * E3, 0) | C14: =ROUND(C3 * E3, 0) | D14: =ROUND(D3 * E3, 0)
A15: Quota Ammortamento Connessione | B15: =ROUND(B4 * E4, 0) | C15: =ROUND(C4 * E4, 0) | D15: =ROUND(D4 * E4, 0)
A16: Quota Ammortamento Sviluppo | B16: =ROUND(B5 * E5, 0) | C16: =ROUND(C5 * E5, 0) | D16: =ROUND(D5 * E5, 0)
A17: Quota Ammortamento Terreni DDS Att. | B17: =ROUND(B8 * E8, 0) | C17: =ROUND(C8 * E8, 0) | D17: =ROUND(D8 * E8, 0)
A19: TOTALE AMMORTAMENTO ANNUALE (€) | B19: =SUM(B13:B17) | C19: =SUM(C13:C17) | D19: =SUM(D13:D17)

Sheet OPEX
A1: Voci di Costo OPEX | B1: Guasticce (Anno 1) | C1: Castenaso (Anno 1) | D1: TOTALE PORTAFOGLIO (Anno 1)
A2: di cui: O&M Impianti (€) | B2: 62700 | C2: 60000 | D2: 122700
A3: di cui: O&M BESS (€) | B3: 0 | C3: 0 | D3: 0
A4: di cui: Costo Ricarica BESS da Rete (€) | B4: 0 | C4: 0 | D4: 0
A5: di cui: Assicurazione (€) | B5: 15000 | C5: 15000 | D5: 30000
A6: di cui: IMU/TASI (€) | B6: 10400 | C6: 12500 | D6: 22900
A7: di cui: Security (€) | B7: 0 | C7: 0 | D7: 0
A8: di cui: Asset Management (€) | B8: 60000 | C8: 60000 | D8: 120000
A9: di cui: DDS Terreni Annuo (€) | B9: 0 | C9: 0 | D9: 0
A10: di cui: BESS Maint. Reserve Accantonata (€) | B10: 0 | C10: 0 | D10: 0
A12: TOTALE OPEX (€) | B12: =SUM(B2:B10) | C12: =SUM(C2:C10) | D12: =SUM(D2:D10)

Sheet CONTO ECONOMICO
A1: DRIVER OPERATIVI | B1: Anno 1 | C1: Anno 2 | D1: Anno 3 | E1: Anno 4 | F1: Anno 5
A2: RICAVI TOTALI SPV (€) | B2: =B3+B4+B5+B6 | C2: =C3+C4+C5+C6 | D2: =D3+D4+D5+D6 | E2: =E3+E4+E5+E6 | F2: =F3+F4+F5+F6
A3: di cui: Ricavi da RID generato da FV (€) | B3: =IFERROR('DRIVER OPERATIVI'!B5*'DRIVER OPERATIVI'!B23, 0) | C3: =IFERROR('DRIVER OPERATIVI'!C5*'DRIVER OPERATIVI'!C23, 0) | D3: =IFERROR('DRIVER OPERATIVI'!D5*'DRIVER OPERATIVI'!D23, 0) | E3: =IFERROR('DRIVER OPERATIVI'!E5*'DRIVER OPERATIVI'!E23, 0) | F3: =IFERROR('DRIVER OPERATIVI'!F5*'DRIVER OPERATIVI'!F23, 0)
A4: di cui: Ricavi da PPA (FV + BESS) (€) | B4: =IFERROR('DRIVER OPERATIVI'!B4*'DRIVER OPERATIVI'!B22 + 'DRIVER OPERATIVI'!B8*'DRIVER OPERATIVI'!B25, 0) | C4: =IFERROR('DRIVER OPERATIVI'!C4*'DRIVER OPERATIVI'!C22 + 'DRIVER OPERATIVI'!C8*'DRIVER OPERATIVI'!C25, 0) | D4: =IFERROR('DRIVER OPERATIVI'!D4*'DRIVER OPERATIVI'!D22 + 'DRIVER OPERATIVI'!D8*'DRIVER OPERATIVI'!D25, 0) | E4: =IFERROR('DRIVER OPERATIVI'!E4*'DRIVER OPERATIVI'!E22 + 'DRIVER OPERATIVI'!E8*'DRIVER OPERATIVI'!E25, 0) | F4: =IFERROR('DRIVER OPERATIVI'!F4*'DRIVER OPERATIVI'!F22 + 'DRIVER OPERATIVI'!F8*'DRIVER OPERATIVI'!F25, 0)
A5: di cui: Ricavi da Time Shifting (€) | B5: =IFERROR('DRIVER OPERATIVI'!B11*'DRIVER OPERATIVI'!B28, 0) | C5: =IFERROR('DRIVER OPERATIVI'!C11*'DRIVER OPERATIVI'!C28, 0) | D5: =IFERROR('DRIVER OPERATIVI'!D11*'DRIVER OPERATIVI'!D28, 0) | E5: =IFERROR('DRIVER OPERATIVI'!E11*'DRIVER OPERATIVI'!E28, 0) | F5: =IFERROR('DRIVER OPERATIVI'!F11*'DRIVER OPERATIVI'!F28, 0)
A6: di cui: Ricavi da Arbitraggio (€) | B6: =IFERROR('DRIVER OPERATIVI'!B10*'DRIVER OPERATIVI'!B27, 0) | C6: =IFERROR('DRIVER OPERATIVI'!C10*'DRIVER OPERATIVI'!C27, 0) | D6: =IFERROR('DRIVER OPERATIVI'!D10*'DRIVER OPERATIVI'!D27, 0) | E6: =IFERROR('DRIVER OPERATIVI'!E10*'DRIVER OPERATIVI'!E27, 0) | F6: =IFERROR('DRIVER OPERATIVI'!F10*'DRIVER OPERATIVI'!F27, 0)
A8: (-) COSTI OPERATIVI (OPEX) TOTALE SPV (€) | B8: =B9+B10+B11+B12+B13+B14+B15+B16+B17 | C8: =C9+C10+C11+C12+C13+C14+C15+C16+C17 | D8: =D9+D10+D11+D12+D13+D14+D15+D16+D17 | E8: =E9+E10+E11+E12+E13+E14+E15+E16+E17 | F8: =F9+F10+F11+F12+F13+F14+F15+F16+F17
A9: di cui: O&M Impianti Fotovoltaici (€) | B9: =IFERROR(-OPEX!D2, 0) | C9: =IFERROR(ROUND(B9 * (1 + 'DRIVER OPERATIVI'!C16), 0), 0) | D9: =IFERROR(ROUND(C9 * (1 + 'DRIVER OPERATIVI'!D16), 0), 0) | E9: =IFERROR(ROUND(D9 * (1 + 'DRIVER OPERATIVI'!E16), 0), 0) | F9: =IFERROR(ROUND(E9 * (1 + 'DRIVER OPERATIVI'!F16), 0), 0)
A10: di cui: Costi Operativi BESS (€) | B10: =IFERROR(-OPEX!D3, 0) | C10: =IFERROR(ROUND(B10 * (1 + 'DRIVER OPERATIVI'!C16), 0), 0) | D10: =IFERROR(ROUND(C10 * (1 + 'DRIVER OPERATIVI'!D16), 0), 0) | E10: =IFERROR(ROUND(D10 * (1 + 'DRIVER OPERATIVI'!E16), 0), 0) | F10: =IFERROR(ROUND(E10 * (1 + 'DRIVER OPERATIVI'!F16), 0), 0)
A11: di cui: Costo Energia Pre-carica da Rete BESS (€) | B11: =IFERROR(-('DRIVER OPERATIVI'!B12*'DRIVER OPERATIVI'!B29), 0) | C11: =IFERROR(-('DRIVER OPERATIVI'!C12*'DRIVER OPERATIVI'!C29), 0) | D11: =IFERROR(-('DRIVER OPERATIVI'!D12*'DRIVER OPERATIVI'!D29), 0) | E11: =IFERROR(-('DRIVER OPERATIVI'!E12*'DRIVER OPERATIVI'!E29), 0) | F11: =IFERROR(-('DRIVER OPERATIVI'!F12*'DRIVER OPERATIVI'!F29), 0)
A12: di cui: Canone DDS/Affitto Terreno (€) | B12: =IFERROR(-OPEX!D9, 0) | C12: =IFERROR(ROUND(B12 * (1 + 'DRIVER OPERATIVI'!C16), 0), 0) | D12: =IFERROR(ROUND(C12 * (1 + 'DRIVER OPERATIVI'!D16), 0), 0) | E12: =IFERROR(ROUND(D12 * (1 + 'DRIVER OPERATIVI'!E16), 0), 0) | F12: =IFERROR(ROUND(E12 * (1 + 'DRIVER OPERATIVI'!F16), 0), 0)
A13: di cui: Assicurazione (All Risk / RC) (€) | B13: =IFERROR(-OPEX!D5, 0) | C13: =IFERROR(ROUND(B13 * (1 + 'DRIVER OPERATIVI'!C16), 0), 0) | D13: =IFERROR(ROUND(C13 * (1 + 'DRIVER OPERATIVI'!D16), 0), 0) | E13: =IFERROR(ROUND(D13 * (1 + 'DRIVER OPERATIVI'!E16), 0), 0) | F13: =IFERROR(ROUND(E13 * (1 + 'DRIVER OPERATIVI'!F16), 0), 0)
A14: di cui: Tasse Locali / IMU (€) | B14: =IFERROR(-OPEX!D6, 0) | C14: =IFERROR(ROUND(B14 * (1 + 'DRIVER OPERATIVI'!C16), 0), 0) | D14: =IFERROR(ROUND(C14 * (1 + 'DRIVER OPERATIVI'!D16), 0), 0) | E14: =IFERROR(ROUND(D14 * (1 + 'DRIVER OPERATIVI'!E16), 0), 0) | F14: =IFERROR(ROUND(E14 * (1 + 'DRIVER OPERATIVI'!F16), 0), 0)
A15: di cui: Vigilanza & Sicurezza (€) | B15: =IFERROR(-OPEX!D7, 0) | C15: =IFERROR(ROUND(B15 * (1 + 'DRIVER OPERATIVI'!C16), 0), 0) | D15: =IFERROR(ROUND(C15 * (1 + 'DRIVER OPERATIVI'!D16), 0), 0) | E15: =IFERROR(ROUND(D15 * (1 + 'DRIVER OPERATIVI'!E16), 0), 0) | F15: =IFERROR(ROUND(E15 * (1 + 'DRIVER OPERATIVI'!F16), 0), 0)
A16: di cui: Gestione Amministrativa & Asset Mgt (€) | B16: =IFERROR(-OPEX!D8, 0) | C16: =IFERROR(ROUND(B16 * (1 + 'DRIVER OPERATIVI'!C16), 0), 0) | D16: =IFERROR(ROUND(C16 * (1 + 'DRIVER OPERATIVI'!D16), 0), 0) | E16: =IFERROR(ROUND(D16 * (1 + 'DRIVER OPERATIVI'!E16), 0), 0) | F16: =IFERROR(ROUND(E16 * (1 + 'DRIVER OPERATIVI'!F16), 0), 0)
A17: di cui: Contratto di Servizio Commerciale PPA (€) | B17: =IFERROR(-ROUND('DRIVER OPERATIVI'!B22 * 'DRIVER OPERATIVI'!B4 * 'DRIVER OPERATIVI'!B17, 0), 0) | C17: =IFERROR(-ROUND('DRIVER OPERATIVI'!C22 * 'DRIVER OPERATIVI'!C4 * 'DRIVER OPERATIVI'!C17, 0), 0) | D17: =IFERROR(-ROUND('DRIVER OPERATIVI'!D22 * 'DRIVER OPERATIVI'!D4 * 'DRIVER OPERATIVI'!D17, 0), 0) | E17: =IFERROR(-ROUND('DRIVER OPERATIVI'!E22 * 'DRIVER OPERATIVI'!E4 * 'DRIVER OPERATIVI'!E17, 0), 0) | F17: =IFERROR(-ROUND('DRIVER OPERATIVI'!F22 * 'DRIVER OPERATIVI'!F4 * 'DRIVER OPERATIVI'!F17, 0), 0)
A19: MARGINE OPERATIVO LORDO (EBITDA) (€) | B19: =B2+B8 | C19: =C2+C8 | D19: =D2+D8 | E19: =E2+E8 | F19: =F2+F8
A21: (-) Ammortamento Civilistico (€) | B21: =IF(1 <= 12, IFERROR(-CAPEX!E19, 0), 0) | C21: =IF(2 <= 12, IFERROR(-CAPEX!E19, 0), 0) | D21: =IF(3 <= 12, IFERROR(-CAPEX!E19, 0), 0) | E21: =IF(4 <= 12, IFERROR(-CAPEX!E19, 0), 0) | F21: =IF(5 <= 12, IFERROR(-CAPEX!E19, 0), 0)
A22: di cui: Ammortamento Impianti Solari (€) | B22: =IF(1 <= 12, IFERROR(-CAPEX!E13, 0), 0) | C22: =IF(2 <= 12, IFERROR(-CAPEX!E13, 0), 0) | D22: =IF(3 <= 12, IFERROR(-CAPEX!E13, 0), 0) | E22: =IF(4 <= 12, IFERROR(-CAPEX!E13, 0), 0) | F22: =IF(5 <= 12, IFERROR(-CAPEX!E13, 0), 0)
A23: di cui: Ammortamento BESS (€) | B23: =IF(1 <= 12, IFERROR(-CAPEX!E14, 0), 0) | C23: =IF(2 <= 12, IFERROR(-CAPEX!E14, 0), 0) | D23: =IF(3 <= 12, IFERROR(-CAPEX!E14, 0), 0) | E23: =IF(4 <= 12, IFERROR(-CAPEX!E14, 0), 0) | F23: =IF(5 <= 12, IFERROR(-CAPEX!E14, 0), 0)
A24: di cui: Ammortamento Altri Costi Capitalizzati (€) | B24: =IF(1 <= 12, IFERROR(-(CAPEX!E15 + CAPEX!E16 + CAPEX!E17), 0), 0) | C24: =IF(2 <= 12, IFERROR(-(CAPEX!E15 + CAPEX!E16 + CAPEX!E17), 0), 0) | D24: =IF(3 <= 12, IFERROR(-(CAPEX!E15 + CAPEX!E16 + CAPEX!E17), 0), 0) | E24: =IF(4 <= 12, IFERROR(-(CAPEX!E15 + CAPEX!E16 + CAPEX!E17), 0), 0) | F24: =IF(5 <= 12, IFERROR(-(CAPEX!E15 + CAPEX!E16 + CAPEX!E17), 0), 0)
A26: EBIT SPV (Risultato Operativo) (€) | B26: =B19+B21 | C26: =C19+C21 | D26: =D19+D21 | E26: =E19+E21 | F26: =F19+F21
A28: (+) Interessi Attivi su MRA (€) | B28: 0 | C28: 0 | D28: 0 | E28: 0 | F28: 0
A29: (-) Interessi Passivi Mutuo Bancario (€) | B29: -202419.13 | C29: -173484.35 | D29: -144278.25 | E29: -114752.92 | F29: -84860.636
A30: (-) Interessi Finanziamento Soci (Accrual) (5.50%) (€) | B30: 0 | C30: 0 | D30: 0 | E30: 0 | F30: 0
A32: EBT — Utile ante Imposte SPV (€) | B32: =B26+B28+B29+B30 | C32: =C26+C28+C29+C30 | D32: =D26+D28+D29+D30 | E32: =E26+E28+E29+E30 | F32: =F26+F28+F29+F30
A34: (-) Imposte Correnti SPV (IRES 24% + IRAP 3.9%) (€) | B34: -172515.39 | C34: -164444.49 | D34: -157078.63 | E34: -150393.05 | F34: -144364.83
A35: (-/+) Variazione Imposte Differite (⇒ Sez. B) (€) | B35: -1.6239937e-11 | C35: -1.6239937e-11 | D35: -1.6239937e-11 | E35: -1.6239937e-11 | F35: -1.6239937e-11
A37: UTILE NETTO CIVILISTICO SPV (⇒ Sez. B) (€) | B37: =B32+B34+B35 | C37: =C32+C34+C35 | D37: =D32+D34+D35 | E37: =E32+E34+E35 | F37: =F32+F34+F35

Sheet RENDICONTO FINANZIARIO SPV
A1: DRIVER OPERATIVI | B1: Anno 1 | C1: Anno 2 | D1: Anno 3 | E1: Anno 4 | F1: Anno 5
A2: ⇒ Utile Netto Civilistico SPV (da Sez. A) (€) | B2: ='CONTO ECONOMICO'!B37 | C2: ='CONTO ECONOMICO'!C37 | D2: ='CONTO ECONOMICO'!D37 | E2: ='CONTO ECONOMICO'!E37 | F2: ='CONTO ECONOMICO'!F37
A3: (+) Ripresa Ammortamento Civilistico (Non-Cash) (€) | B3: =-('CONTO ECONOMICO'!B21) | C3: =-('CONTO ECONOMICO'!C21) | D3: =-('CONTO ECONOMICO'!D21) | E3: =-('CONTO ECONOMICO'!E21) | F3: =-('CONTO ECONOMICO'!F21)
A4: (+/-) Ripresa Imposte Differite (da Sez. A) (€) | B4: ='CONTO ECONOMICO'!B35 | C4: ='CONTO ECONOMICO'!C35 | D4: ='CONTO ECONOMICO'!D35 | E4: ='CONTO ECONOMICO'!E35 | F4: ='CONTO ECONOMICO'!F35
A5: (+) Ripresa Interessi Mutuo Bancario Senior (Accrual) (€) | B5: =-('CONTO ECONOMICO'!B29) | C5: =-('CONTO ECONOMICO'!C29) | D5: =-('CONTO ECONOMICO'!D29) | E5: =-('CONTO ECONOMICO'!E29) | F5: =-('CONTO ECONOMICO'!F29)
A6: (+) Ripresa Interessi Finanziamento Soci (Accrual) (€) | B6: =-('CONTO ECONOMICO'!B30) | C6: =-('CONTO ECONOMICO'!C30) | D6: =-('CONTO ECONOMICO'!D30) | E6: =-('CONTO ECONOMICO'!E30) | F6: =-('CONTO ECONOMICO'!F30)
A7: (-) Accantonamento a Riserva di Manutenzione (MRA) (€) | B7: 0 | C7: 0 | D7: 0 | E7: 0 | F7: 0
A8: (-) CAPEX Sostituzione Celle NMC/LFP BESS (€) | B8: 0 | C8: 0 | D8: 0 | E8: 0 | F8: 0
A9: (+) Rilascio Riserva di Manutenzione (MRA) per CAPEX BESS (€) | B9: 0 | C9: 0 | D9: 0 | E9: 0 | F9: 0
A11: CFADS SPV (Cassa Disponibile ante Servizio Debito) (€) | B11: =B2+B3+B4+B5+B6+B7+B8+B9 | C11: =C2+C3+C4+C5+C6+C7+C8+C9 | D11: =D2+D3+D4+D5+D6+D7+D8+D9 | E11: =E2+E3+E4+E5+E6+E7+E8+E9 | F11: =F2+F3+F4+F5+F6+F7+F8+F9
A13: SERVIZIO DEL DEBITO SENIOR MUTUO BANCARIO SPV
A14: (-) Quota Interessi Mutuo Bancario Pagati (€) | B14: -202419.13 | C14: -173484.35 | D14: -144278.25 | E14: -114752.92 | F14: -84860.636
A15: (-) Quota Capitale Mutuo Bancario Programmata (€) | B15: -366058.46 | C15: -394993.24 | D15: -424199.34 | E15: -453724.68 | F15: -483616.96
A16: (-) Cash Sweep Mutuo Bancario Volontario (€) | B16: -276936.74 | C16: -254031.14 | D16: -231919.19 | E16: -210548.29 | F16: -189868.27
A17: Sweep: 50% del CFADS disponibile — per 5 anni | B17: 0 | C17: 0 | D17: 0 | E17: 0 | F17: 0
A19: CASSA DISPONIBILE POST-DEBITO SENIOR (FCFE SPV) (€) | B19: =B11+B14+B15+B16 | C19: =C11+C14+C15+C16 | D19: =D11+D14+D15+D16 | E19: =E11+E14+E15+E16 | F19: =F11+F14+F15+F16
A21: CASCATA DISTRIBUZIONE SPV → HOLDCO (Waterfall)
A22: (-) Interessi Soci Pagati da SPV a HoldCo (⇒ Sez. C) (€) | B22: 0 | C22: 0 | D22: 0 | E22: 0 | F22: 0
A23: (-) Rimborso Capitale Finanziamento Soci a HoldCo (⇒ Sez. C) (€) | B23: 0 | C23: 0 | D23: 0 | E23: 0 | F23: 0
A24: (-) Dividendi SPV Distribuiti a HoldCo (⇒ Sez. C) (€) | B24: 0 | C24: 0 | D24: 0 | E24: 0 | F24: -1163303.6
A26: (=) Cassa Rimanente non distribuita in SPV (Cash Trap) (€) | B26: =MAX(B19+B22+B23+B24, 0) | C26: =MAX(C19+C22+C23+C24, 0) | D26: =MAX(D19+D22+D23+D24, 0) | E26: =MAX(E19+E22+E23+E24, 0) | F26: =MAX(F19+F22+F23+F24, 0)

Sheet RENDICONTO FINANZIARIO HOLDING
A1: DRIVER OPERATIVI | B1: Anno 1 | C1: Anno 2 | D1: Anno 3 | E1: Anno 4 | F1: Anno 5
A2: ⇒ Flusso Cassa Risalito Totale da SPV (da Sez. B) (€) | B2: =B3+B4+B5+B6 | C2: =C3+C4+C5+C6 | D2: =D3+D4+D5+D6 | E2: =E3+E4+E5+E6 | F2: =F3+F4+F5+F6
A3: di cui: Interessi Finanziamento Soci ricevuti (€) | B3: =-('RENDICONTO FINANZIARIO SPV'!B22) | C3: =-('RENDICONTO FINANZIARIO SPV'!C22) | D3: =-('RENDICONTO FINANZIARIO SPV'!D22) | E3: =-('RENDICONTO FINANZIARIO SPV'!E22) | F3: =-('RENDICONTO FINANZIARIO SPV'!F22)
A4: di cui: Rimborso Capitale Finanziamento Soci ricevuto (€) | B4: =-('RENDICONTO FINANZIARIO SPV'!B23) | C4: =-('RENDICONTO FINANZIARIO SPV'!C23) | D4: =-('RENDICONTO FINANZIARIO SPV'!D23) | E4: =-('RENDICONTO FINANZIARIO SPV'!E23) | F4: =-('RENDICONTO FINANZIARIO SPV'!F23)
A5: di cui: Dividendi SPV ricevuti (€) | B5: =-('RENDICONTO FINANZIARIO SPV'!B24) | C5: =-('RENDICONTO FINANZIARIO SPV'!C24) | D5: =-('RENDICONTO FINANZIARIO SPV'!D24) | E5: =-('RENDICONTO FINANZIARIO SPV'!E24) | F5: =-('RENDICONTO FINANZIARIO SPV'!F24)
A6: di cui: Ricavi Gestione Amministrativa & Asset Mgt ricevuti da SPV (€) | B6: =-('CONTO ECONOMICO'!B16) | C6: =-('CONTO ECONOMICO'!C16) | D6: =-('CONTO ECONOMICO'!D16) | E6: =-('CONTO ECONOMICO'!E16) | F6: =-('CONTO ECONOMICO'!F16)
A7: (-) Spese Funzionamento Holding (€) | B7: -15000 | C7: -15300 | D7: -15606 | E7: -15918.12 | F7: -16236.482
A8: (-) Earn-Out Holding (€) | B8: -17020.965 | C8: -16113.322 | D8: -15253.891 | E8: -14440.119 | F8: -13669.59
A9: (-) Imposta IRES HoldCo (24% su interessi netti e 5% dividendi) (€) | B9: -25200 | C9: -25704 | D9: -26218.08 | E9: -26742.442 | F9: -41236.934
A11: UTILE NETTO HOLDING CIVILISTICO (€) | B11: =B3+B5+B6+B7+B8+B9 | C11: =C3+C5+C6+C7+C8+C9 | D11: =D3+D5+D6+D7+D8+D9 | E11: =E3+E5+E6+E7+E8+E9 | F11: =F3+F5+F6+F7+F8+F9
A12: (+) Rimborso Capitale Finanziamento Soci (Cassa Patrimoniale) (€) | B12: =-('RENDICONTO FINANZIARIO SPV'!B23) | C12: =-('RENDICONTO FINANZIARIO SPV'!C23) | D12: =-('RENDICONTO FINANZIARIO SPV'!D23) | E12: =-('RENDICONTO FINANZIARIO SPV'!E23) | F12: =-('RENDICONTO FINANZIARIO SPV'!F23)
A14: FLUSSO DA DISMISSIONE INVESTIMENTO (EXIT) (€) | B14: =B15+B16+B17 | C14: =C15+C16+C17 | D14: =D15+D16+D17 | E14: =E15+E16+E17 | F14: =F15+F16+F17
A15: di cui: Enterprise Value di Exit (€) | B15: =0 | C15: =0 | D15: =0 | E15: =0 | F15: =FINANZA!$B$25 * ('DRIVER OPERATIVI'!F18 / 1000)
A16: (-) di cui: Rimborso Debito Residuo Mutuo Bancario (€) | B16: =0 | C16: =0 | D16: =0 | E16: =0 | F16: =-AMMORTAMENTO!F8
A17: (-) di cui: Imposte PEX su Plusvalenza Exit (€) | B17: 0 | C17: 0 | D17: 0 | E17: 0 | F17: -46150.468
A19: FCFE — FLUSSO NETTO INVESTITORE (€) | B19: =B11+B12+B14 | C19: =C11+C12+C14 | D19: =D11+D12+D14 | E19: =E11+E12+E14 | F19: =F11+F12+F14
A20: FCFE CUMULATO INVESTITORE (€) | B20: =B19 | C20: =B20+C19 | D20: =C20+D19 | E20: =D20+E19 | F20: =E20+F19

Sheet FINANZA
A1: PARAMETRI E STRUTTURA FINANZIARIA | B1: Valore | C1: %
A2: TASSI E RENDIMENTI (MACRO)
A3: Ke Valutativo (Cost of Equity) | B3: 0.08
A4: WACC (Weighted Average Cost of Capital) | B4: 0.06
A5: Inflazione Media Attesa | B5: 0.02
A6: Tasso di Ammortamento Fiscale | B6: 0.09
A8: STRUTTURA DEL DEBITO & CASH SWEEP
A9: Leverage (D/E Ratio Target) | B9: 0.75
A10: Tasso Interesse Debito Senior | B10: 0.045
A11: Base di Calcolo Debito (Debt Basis) | B11: Totale Investimento al netto SPV
A12: Durata Debito Senior (Anni) | B12: 10
A13: Tipo di Cash Sweep | B13: % del CFADS
A14: Valore Cash Sweep (%) | B14: 0.5
A15: Anni di Blocco Cash Sweep | B15: 5
A17: FINANZIAMENTO SOCI E HOLDING
A18: Quota Equity Finanziata dai Soci (%) | B18: 1
A19: Tasso Interesse Finanziamento Soci | B19: 0.055
A20: Preammortamento Interessi Soci (Anni) | B20: 10
A21: Preammortamento Capitale Soci (Anni) | B21: 10
A22: Capitale Iniziale Holding (€) | B22: 10000
A23: Opzione di Uscita (Exit Strategy) | B23: Uscita a Fine Anno 5 (RTB)
A24: Multiplo EBITDA di Uscita (x) | B24: 6.7432929
A25: Valutazione di Uscita per MWp (€) | B25: 900000
A26: Valutazione Enterprise Value Fissa (€) | B26: 7367580
A28: SCENARI PREZZI E VINCOLI
A29: Scenario Curve di Prezzo | B29: Caso Base (PUN GME)
A30: Prezzo Floor Minimo ZONALE (€/MWh) | B30: 75
A31: Tasso Decadimento Bearish Annuo (%) | B31: 0.05
A32: Blocco Dividendi Fino Estinzione Debito | B32: SÌ
A34: TOTALE USI E BASE FINANZIABILE
A35: Costo Totale Progetto (CAPEX) | B35: =CAPEX!D10
A36: Costo Acquisizione SPV (Da escludere se base ev_ex_spv) | B36: =CAPEX!D6
A37: Capitale Sociale HoldCo (Da versare) | B37: 10000
A38: TOTALE FABBISOGNO (Usi) | B38: =B35 + B37 | C38: 1
A39: Base Finanziabile Effettiva | B39: =B35 - B36
A41: TOTALE FONTI (Coperture)
A42: Debito Bancario (Senior Loan) | B42: =IF(B12 > 0, B39 * B9, 0) | C42: =IFERROR(B42 / B38, 0)
A43: Totale Equity (Mezzi Propri) | B43: =B38 - B42 | C43: =IFERROR(B43 / B38, 0)
A44: - Capitale Sociale HoldCo (Versato) | B44: =B37
A45: - Finanziamento Soci (Subordinated Debt) | B45: =MAX(0, B35 - B36 - B42) * B18
...

Sheet AMMORTAMENTO
A1: DRIVER OPERATIVI | B1: Anno 1 | C1: Anno 2 | D1: Anno 3 | E1: Anno 4 | F1: Anno 5
A3: 1. DEBITO BANCARIO SPV – Project Finance (Senior Debt) | B3: 0 | C3: 0 | D3: 0 | E3: 0 | F3: 0
A4: Debito Residuo Inizio Anno (€) | B4: 4498203 | C4: =B8 | D4: =C8 | E4: =D8 | F4: =E8
A5: (-) Quota Interessi Mutuo Maturati (€) | B5: =-IF(1 <= FINANZA!$B$12, MAX(0, B4) * FINANZA!$B$10, 0) | C5: =-IF(2 <= FINANZA!$B$12, MAX(0, C4) * FINANZA!$B$10, 0) | D5: =-IF(3 <= FINANZA!$B$12, MAX(0, D4) * FINANZA!$B$10, 0) | E5: =-IF(4 <= FINANZA!$B$12, MAX(0, E4) * FINANZA!$B$10, 0) | F5: =-IF(5 <= FINANZA!$B$12, MAX(0, F4) * FINANZA!$B$10, 0)
A6: (-) Quota Capitale Programmata (€) | B6: =MAX(-B4, IF(1 <= FINANZA!$B$12, PPMT(FINANZA!$B$10, 1, FINANZA!$B$12, FINANZA!$B$42), 0)) | C6: =MAX(-C4, IF(2 <= FINANZA!$B$12, PPMT(FINANZA!$B$10, 2, FINANZA!$B$12, FINANZA!$B$42), 0)) | D6: =MAX(-D4, IF(3 <= FINANZA!$B$12, PPMT(FINANZA!$B$10, 3, FINANZA!$B$12, FINANZA!$B$42), 0)) | E6: =MAX(-E4, IF(4 <= FINANZA!$B$12, PPMT(FINANZA!$B$10, 4, FINANZA!$B$12, FINANZA!$B$42), 0)) | F6: =MAX(-F4, IF(5 <= FINANZA!$B$12, PPMT(FINANZA!$B$10, 5, FINANZA!$B$12, FINANZA!$B$42), 0))
A7: (-) Quota Capitale Prepagata - Cash Sweep (€) | B7: =-IF(1 < FINANZA!$B$15, MAX(0, MIN(B4 + B6, IF(FINANZA!$B$13="% del CFADS", ('RENDICONTO FINANZIARIO SPV'!B11 + B5 + B6) * FINANZA!$B$14, IF(FINANZA!$B$13="€ Fisso/Anno", FINANZA!$B$14, 0)))), 0) | C7: =-IF(2 < FINANZA!$B$15, MAX(0, MIN(C4 + C6, IF(FINANZA!$B$13="% del CFADS", ('RENDICONTO FINANZIARIO SPV'!C11 + C5 + C6) * FINANZA!$B$14, IF(FINANZA!$B$13="€ Fisso/Anno", FINANZA!$B$14, 0)))), 0) | D7: =-IF(3 < FINANZA!$B$15, MAX(0, MIN(D4 + D6, IF(FINANZA!$B$13="% del CFADS", ('RENDICONTO FINANZIARIO SPV'!D11 + D5 + D6) * FINANZA!$B$14, IF(FINANZA!$B$13="€ Fisso/Anno", FINANZA!$B$14, 0)))), 0) | E7: =-IF(4 < FINANZA!$B$15, MAX(0, MIN(E4 + E6, IF(FINANZA!$B$13="% del CFADS", ('RENDICONTO FINANZIARIO SPV'!E11 + E5 + E6) * FINANZA!$B$14, IF(FINANZA!$B$13="€ Fisso/Anno", FINANZA!$B$14, 0)))), 0) | F7: =-IF(5 < FINANZA!$B$15, MAX(0, MIN(F4 + F6, IF(FINANZA!$B$13="% del CFADS", ('RENDICONTO FINANZIARIO SPV'!F11 + F5 + F6) * FINANZA!$B$14, IF(FINANZA!$B$13="€ Fisso/Anno", FINANZA!$B$14, 0)))), 0)
A8: Debito Residuo Fine Anno (€) | B8: =MAX(0, B4 + B6 + B7) | C8: =MAX(0, C4 + C6 + C7) | D8: =MAX(0, D4 + D6 + D7) | E8: =MAX(0, E4 + E6 + E7) | F8: =MAX(0, F4 + F6 + F7)
A10: SERVIZIO DEL DEBITO EFFETTIVO (€) | B10: =B5+B6+B7 | C10: =C5+C6+C7 | D10: =D5+D6+D7 | E10: =E5+E6+E7 | F10: =F5+F6+F7
A11: DSCR (Debt Service Coverage Ratio) | B11: =IFERROR('RENDICONTO FINANZIARIO SPV'!B11/-(B5+B6), 0) | C11: =IFERROR('RENDICONTO FINANZIARIO SPV'!C11/-(C5+C6), 0) | D11: =IFERROR('RENDICONTO FINANZIARIO SPV'!D11/-(D5+D6), 0) | E11: =IFERROR('RENDICONTO FINANZIARIO SPV'!E11/-(E5+E6), 0) | F11: =IFERROR('RENDICONTO FINANZIARIO SPV'!F11/-(F5+F6), 0)
A13: 2. FINANZIAMENTO SOCI – Subordinated Shareholder Loan (100% Equity) | B13: 0 | C13: 0 | D13: 0 | E13: 0 | F13: 0
A14: Finanziamento Soci Inizio Anno (€) | B14: 1499401 | C14: =B18 | D14: =C18 | E14: =D18 | F14: =E18
A15: (-) Interessi Maturati (5.50% p.a., grazia anni 1-10) (€) | B15: 0 | C15: 0 | D15: 0 | E15: 0 | F15: 0
A16: (+) Interessi Pagati Effettivamente (€) | B16: 0 | C16: 0 | D16: 0 | E16: 0 | F16: 0
A17: (-) Rimborso Quota Capitale (grazia anni 1-10) (€) | B17: 0 | C17: 0 | D17: 0 | E17: 0 | F17: 0
A18: Finanziamento Soci Fine Anno (€) | B18: =B14-B15-B16+B17 | C18: =C14-C15-C16+C17 | D18: =D14-D15-D16+D17 | E18: =E14-E15-E16+E17 | F18: =F14-F15-F16+F17
